Workbook

Sheet Export Summary
B3: This document was exported from Numbers. Each table was converted to an Excel worksheet. All other objects on each Numbers sheet were placed on separate worksheets. Please be aware that formula calculations may differ in Excel.
B7: Numbers Sheet Name | C7: Numbers Table Name | D7: Excel Worksheet Name
B9: Sheet 1
C10: Commercial Levers | D10: Sheet 1 - Commercial Levers
B11: CPT Y2027 Brand New Station
C12: TE Vendor Engagement Scope | D12: CPT Y2027 Brand New Station - T
B13: Y2027 NPI - PRM (Anna)
C14: Resource Availability for Y2027 NPI Support | D14: Y2027 NPI - PRM (Anna) - Resour
C15: Y2026 Loading Breakdown (Apr ~ Sep) | D15: Y2027 NPI - PRM (Anna) - Y2026
B16: Y2027 NPI - Innorev (Fiona)
C17: Resource Availability for Y2027 NPI Support | D17: Y2027 NPI - Innorev (Fiona) - R
C18: Y2026 Loading Breakdown (Apr ~ Sep) | D18: Y2027 NPI - Innorev (Fiona) - Y
B19: Y2027 NPI - JLK (Sean)
C20: Resource Availability for Y2027 NPI Support | D20: Y2027 NPI - JLK (Sean) - Resour
C21: Y2026 Loading Breakdown (Apr ~ Sep) | D21: Y2027 NPI - JLK (Sean) - Y2026
B22: Y2027 NPI - Cencorp (Rick)
C23: Resource Availability for Y2027 NPI Support | D23: Y2027 NPI - Cencorp (Rick) - Re
C24: Y2027 RFP Breakdown | D24: Y2027 NPI - Cencorp (Rick) - Y2
C25: Y2026 MP Loading Breakdown (Apr ~ Sep) | D25: Y2027 NPI - Cencorp (Rick) - Y1
C26: Y2026 MP Matrix | D26: Y2027 NPI - Cencorp (Rick) - Y3
B27: Y2027 NPI - HVS (Gene)
C28: Resource Availability for Y2027 NPI Support | D28: Y2027 NPI - HVS (Gene) - Resour
C29: Y2026 Loading Breakdown (Apr ~ Sep) | D29: Y2027 NPI - HVS (Gene) - Y2026
B30: Y2027 NPI - Pantamaster (JS)
C31: Resource Availability for Y2027 NPI Support | D31: Y2027 NPI - Pantamaster (JS) -
C32: Y2026 Loading Breakdown (Apr ~ Sep) | D32: Y2027 NPI - Pantamaster (JS) -1
B33: Y2027 NPI - CYG (Rick)
C34: Resource Availability for Y2027 NPI Support | D34: Y2027 NPI - CYG (Rick) - Resour
C35: Y2026 MP Loading Breakdown (Apr ~ Sep) | D35: Y2027 NPI - CYG (Rick) - Y2026
B36: Y2027 NPI - Nextas (Jessie)
C37: Resource Availability for Y2027 NPI Support | D37: Y2027 NPI - Nextas (Jessie) - R
C38: Y2026 Loading Breakdown (Apr ~ Sep) | D38: Y2027 NPI - Nextas (Jessie) - Y

Sheet Sheet 1 - Commercial Levers
A1: Commercial Levers
A2: Vendor | B2: VN/CN cost parity | C2: Lot 0 items/cal kit reduction | D2: Labor/processing rates | E2: Retrofit | F2: Flat 10% reduction | G2: Common Module benchmark
A3: Cencorp | B3: Y
A4: JLK | B4: Y
A5: Innorev | B5: Y
A6: HVS
A7: VVDN
A8: PRM
A9: Penta
A10: Amp
A11: CYG
A12: Nextas
A13: Details | B13: Communicated as expectation; timeline pull in | C13: 5%-10% cost reduction | D13: Meet targets from last year as NTE | E13: All conveyors 5% retrofit cost of NB (except gsm exceptions)

Sheet CPT Y2027 Brand New Station - T
A1: TE Vendor Engagement Scope
B2: LOB | C2: Program | D2: Station | E2: Launch Timing | F2: Line Count | G2: Vendor | H2: CN/Global | I2: NPI Location | J2: MP Geo Impacted | K2: SPOR Lock Date | L2: Intercept EIH | M2: Trending GSSM Recommendation | N2: Station Resource/Capacity Supportability (APO Fill - Y/N) | O2: Comments
B3: Phone | C3: V7x | D3: ALS-P Conveyor | E3: Fall’27 | G3: Innorev | H3: China | I3: China | J3: China/India | K3: 46127 | L3: P1 EIH Jun/M | N3: Y - Resource/ capability OK2Ssupport. | O3: 1NB in P1, 1 in P2, 1 in EVT for conveyor; 3x each for standalone
B4: Phone | C4: V7x | D4: ALS-P Conveyor | E4: Fall’27 | G4: JLK | H4: Global | I4: China | J4: China/India | K4: 46127 | L4: P1 EIH Jun/M | N4: Y - Resource/ capability OK2Ssupport.
B5: Phone | C5: V7x | D5: ALS-P Conveyor | E5: Fall’27 | G5: Cencorp | H5: China | I5: China | J5: China/India | K5: 46127 | L5: P1 EIH Jun/M | N5: Y - Resource/ capability OK2Ssupport. | O5: update based on Cencorp shared latest resource plan on 4/17
B6: Phone | C6: V7x | D6: ALS-P Conveyor | E6: Fall’27 | G6: HVS | H6: Global | I6: China | J6: China/India | K6: 46127 | L6: P1 EIH Jun/M | N6: Y - Leveraging 26 experience in ALSP but considering free-PRC and no BOM, can’t catch P1 timeline
B7: Phone | C7: V7x | D7: ALS-P Conveyor | E7: Fall’27 | G7: PRM | H7: China | I7: China | J7: China/India | K7: 46127 | L7: P1 EIH Jun/M | N7: N (insufficient & in-capable resource highlight by x-team during Y2026 iPhone Ramp)
B8: Phone | C8: V7x | D8: ALS-P Conveyor | E8: Fall’27 | G8: VVDN | H8: Global | I8: China | J8: China/India | K8: 46127 | L8: P1 EIH Jun/M | O8: IPO to input
B9: Phone | C9: V7x | D9: Odin conveyor | E9: Fall’27 | G9: Innorev | H9: China | I9: China | J9: China/India | K9: 46127 | L9: P1 EIH Jun/M | N9: N - SQE limitation | O9: Out for RFP
B10: Phone | C10: V7x | D10: Odin conveyor | E10: Fall’27 | G10: JLK | H10: Global | I10: China | J10: China/India | K10: 46127 | L10: P1 EIH Jun/M | N10: Y - Resource/ capability OK2Ssupport.
B11: Phone | C11: V7x | D11: Odin conveyor | E11: Fall’27 | G11: Cencorp | H11: China | I11: China | J11: China/India | K11: 46127 | L11: P1 EIH Jun/M | N11: Y - per Hemik this station is likely to be integrated into Clematis, but regardless it will be incremental design work for Cencorp
B12: Phone | C12: V7x | D12: Odin conveyor | E12: Fall’27 | G12: HVS | H12: Global | I12: China | J12: China/India | K12: 46127 | L12: P1 EIH Jun/M | N12: N - PM and other resource limitation considering new design & Free-PRC / China settlement in 2026
B13: Phone | C13: V7x | D13: Odin conveyor | E13: Fall’27 | G13: VVDN | H13: Global | I13: China | J13: China/India | K13: 46127 | L13: P1 EIH Jun/M | O13: IPO to input
B14: Phone | C14: V7x | D14: IQC AA stations | E14: Fall’27 | G14: Innorev | H14: China | I14: China | J14: China/India | K14: 46127 | L14: P1 EIH Jun/M | N14: Y - Resource/ capability OK2Ssupport.
B15: Phone | C15: V7x | D15: IQC AA stations | E15: Fall’27 | G15: HVS | H15: Global | I15: China | J15: China/India | K15: 46127 | L15: P1 EIH Jun/M | N15: N - PM and other resource limitation considering new design & Free-PRC / China settlement in 2026
B16: Phone | C16: V7x | D16: IQC AA stations | E16: Fall’27 | G16: VVDN | H16: Global | I16: China | J16: China/India | K16: 46127 | L16: P1 EIH Jun/M | O16: IPO to input
B17: Phone | C17: V7x | D17: IQC AA stations | E17: Fall’27 | G17: CYG (already engaged) | H17: Global | I17: China | J17: China/India | K17: 46127 | L17: P1 EIH Jun/M | N17: Y
B18: Phone | C18: V7x | D18: IQC AA stations | E18: Fall’27 | G18: Nextas | H18: China | I18: China | J18: China/India | K18: 46127 | L18: P1 EIH Jun/M | N18: Y
B19: Phone | C19: V7x | D19: DCR/OS Tests | E19: Fall’27 | G19: Innorev | H19: China | I19: China | J19: China/India | K19: 46127 | L19: P1 EIH Jun/M | N19: Y - Resource/ capability OK2Ssupport.
B20: Phone | C20: V7x | D20: DCR/OS Tests | E20: Fall’27 | G20: HVS | H20: Global | I20: China | J20: China/India | K20: 46127 | L20: P1 EIH Jun/M | N20: N - PM and other resource limitation considering new design & Free-PRC / China settlement in 2026
B21: Phone | C21: V7x | D21: DCR/OS Tests | E21: Fall’27 | G21: VVDN | H21: Global | I21: China | J21: China/India | K21: 46127 | L21: P1 EIH Jun/M | O21: IPO to input
B22: Phone | C22: V7x | D22: DCR/OS Tests | E22: Fall’27 | G22: CYG (already engaged) | H22: Global | I22: China | J22: China/India | K22: 46127 | L22: P1 EIH Jun/M | N22: Y
B23: Phone | C23: V7x | D23: DCR/OS Tests | E23: Fall’27 | G23: Nextas | H23: China | I23: China | J23: China/India | K23: 46127 | L23: P1 EIH Jun/M | N23: Y
B24: Phone | C24: V7x | D24: SA-Barbie | E24: Fall’27 | G24: JLK | H24: Global | I24: China | J24: China/India | K24: 46127 | L24: P1 EIH Jun/M | M24: JLK or Cencorp | N24: Y - Resource/ capability OK2Ssupport.
B25: Phone | C25: V7x | D25: SA-Barbie | E25: Fall’27 | G25: Cencorp | H25: China | I25: China | J25: China/India | K25: 46127 | L25: P1 EIH Jun/M | N25: Y - Resource/ capability OK2Ssupport.
B26: Phone | C26: V7x | D26: SA-Barbie | E26: Fall’27 | G26: PRM | H26: China | I26: China | J26: China/India | K26: 46127 | L26: P1 EIH Jun/M | N26: N (insufficient & in-capable resource highlight by x-team during Y2026 iPhone Ramp)
B27: Phone | C27: V7x | D27: SA-Barbie | E27: Fall’27 | G27: Pentamaster | H27: Global | I27: China | J27: China/India | K27: 46127 | L27: P1 EIH Jun/M | N27: Y - Resource/ capability OK2Ssupport.
B28: iPad | C28: J8x7 | D28: DVI Conveyor RFP | G28: Innorev | H28: China | I28: China | J28: China/Vietnam | K28: 46141 | L28: P2 EIH Jun/E | N28: Y - Resource/ capability OK2Ssupport.
B29: iPad | C29: J8x7 | D29: DVI Conveyor RFP | G29: JLK | H29: Global | I29: China | J29: China/Vietnam | K29: 46141 | L29: P2 EIH Jun/E | N29: Y - Resource/ capability OK2Ssupport.
B30: iPad | C30: J8x7 | D30: DVI Conveyor RFP | G30: Cencorp | H30: China | I30: China | J30: China/Vietnam | K30: 46141 | L30: P2 EIH Jun/E | N30: Y - Resource/ capability OK2Ssupport. | O30: update based on Cencorp shared latest resource plan on 4/17
B31: Audio | C31: B798 | D31: ALL in One Case | E31: Fall’27 | G31: Innorev | H31: China | I31: China | J31: China | K31: Open | L31: P2 EIH Jun/E | N31: Y - Resource/ capability OK2Ssupport. | O31: Out for RFP
B32: Audio | C32: B798 | D32: ALL in One Case | E32: Fall’27 | G32: JLK | H32: Global | I32: China | J32: China | K32: Open | L32: P2 EIH Jun/E | N32: No RFP received | O32: Out for RFP
B33: Audio | C33: B798 | D33: ALL in One Case | E33: Fall’27 | G33: PRM | H33: China | I33: China | J33: China | K33: Open | L33: P2 EIH Jun/E | N33: Not received RFP | O33: Out for RFP
B34: Audio | C34: B798 | D34: ALL in One Case | E34: Fall’27 | G34: Pentamaster | H34: Global | I34: China | J34: China | K34: Open | L34: P2 EIH Jun/E | N34: No RFP received | O34: Out for RFP
B35: Audio | C35: B798 | D35: ALL in One Case | E35: Fall’27 | G35: HVS | H35: Global | I35: China | J35: China | K35: Open | L35: P2 EIH Jun/E | N35: Y - already aligned with CPT and list submitted / Capacity & Resource ok to support (Produced in Korea for NPI build) - need to check station name | O35: Out for RFP
B36: Audio | C36: B798 | D36: Open Short | E36: Fall’27 | G36: Innorev | H36: China | I36: China | J36: China | K36: Open | L36: P2 EIH Jun/E | N36: Y - Resource/ capability OK2Ssupport. | O36: Out for RFP
B37: Audio | C37: B798 | D37: Open Short | E37: Fall’27 | G37: JLK | H37: Global | I37: China | J37: China | K37: Open | L37: P2 EIH Jun/E | N37: No RFP received | O37: Out for RFP
B38: Audio | C38: B798 | D38: Open Short | E38: Fall’27 | G38: PRM | H38: China | I38: China | J38: China | K38: Open | L38: P2 EIH Jun/E | N38: Not received RFP | O38: Out for RFP
B39: Audio | C39: B798 | D39: Open Short | E39: Fall’27 | G39: Pentamaster | H39: Global | I39: China | J39: China | K39: Open | L39: P2 EIH Jun/E | N39: No RFP received | O39: Out for RFP
B40: Audio | C40: B798 | D40: Open Short | E40: Fall’27 | G40: HVS | H40: Global | I40: China | J40: China | K40: Open | L40: P2 EIH Jun/E | N40: Y - already aligned with CPT and list submitted / Capacity & Resource ok to support (Produced in Korea for NPI build) - need to check station name | O40: Out for RFP
...

Sheet Y2027 NPI - PRM (Anna) - Resour
A1: Resource Availability for Y2027 NPI Support
A2: SI Name | B2: Resource | C2: Y2026 Loading (Apr’26 ~ Sep’26) | D2: Total Resource (Cut Off Apr wk3) | E2: Resource Occupied for Y2026 Ramp (Apr’26 ~ Sep’26) | F2: Resource Leftover for Y2027 Brand-New Station NPI Build (Apr’26 ~ Sep’26) | G2: # of Stations Type can support (Refer CPT Y2027 RFP) | H2: Station Name can support (Refer CPT Y2027 RFP) | I2: Justification on why resource can support | J2: Space Supportability (Y/N) | K2: Machining Capacity Supportability (Y/N) | L2: Assembly Capacity Supportability (Y/N) | M2: Quality Capacity Supportability (Y/N) | N2: Station Name CANNOT Support (Refer CPT Y2027 RFP) & Justification
A3: PRM | B3: PM | C3: {=SUM(E3:E11)/SUM(D3:D11)} -> 0.67700987 | D3: 69 | E3: {=SUM('Y2027 NPI - PRM (Anna) - Y2026 '!C6:H6)} -> 40 | F3: {=D3-E3} -> 29 | G3: 4x | H3: iPhone V7x Station SA Barbie ALS-P Watch FACT Cyan | I3: Refer to V6x FACTVENT station in similar complexity, NPI resourced required as below: PM- 1x ME - 5x EE - 5x VE - 3x Assembly：18/line Quality- 2x | J3: Y | K3: Y | L3: Y | M3: Y
A4: PRM | B4: ME | D4: 123 | E4: {=SUM('Y2027 NPI - PRM (Anna) - Y2026 '!C7:H7)} -> 61 | F4: {=D4-E4} -> 62
A5: PRM | B5: EE | D5: 75 | E5: {=SUM('Y2027 NPI - PRM (Anna) - Y2026 '!C8:H8)} -> 62 | F5: {=D5-E5} -> 13
A6: PRM | B6: SW | D6: {=5+16+17+24} -> 62 | E6: {=SUM('Y2027 NPI - PRM (Anna) - Y2026 '!C9:H9)} -> 43 | F6: {=D6-E6} -> 19
A7: PRM | B7: FAE | D7: {=55+36} -> 91 | E7: {=SUM('Y2027 NPI - PRM (Anna) - Y2026 '!C10:H10)} -> 67 | F7: {=D7-E7} -> 24
A8: PRM | B8: Assembly | D8: {=40+88+48} -> 176 | E8: {=SUM('Y2027 NPI - PRM (Anna) - Y2026 '!C11:H11)} -> 111 | F8: {=D8-E8} -> 65
A9: PRM | B9: Debug | D9: {=34+21} -> 55 | E9: {=SUM('Y2027 NPI - PRM (Anna) - Y2026 '!C12:H12)} -> 52 | F9: {=D9-E9} -> 3
A10: PRM | B10: Quality | D10: {=13+32} -> 45 | E10: {=SUM('Y2027 NPI - PRM (Anna) - Y2026 '!C13:H13)} -> 38 | F10: {=D10-E10} -> 7
A11: PRM | B11: VE | D11: 13 | E11: {=SUM('Y2027 NPI - PRM (Anna) - Y2026 '!C14:H14)} -> 6 | F11: {=D11-E11} -> 7

Sheet Y2027 NPI - PRM (Anna) - Y2026 
A1: Y2026 Loading Breakdown (Apr ~ Sep)
A2: SI Name | B2: Items | C2: Portable | D2: Pad | E2: Desktop | F2: Audio | G2: Watch | H2: Phone
A3: PRM | B3: Program | C3: J701/K104/J91a/K11p | D3: J8x7/J9xx/J510 | E3: J775/J873/J883/J83x | F3: B798/B868/B790/B747a/B727 | G3: N23x/N240 | H3: V68/V6X
A4: PRM | B4: Station Name | C4: Snoop/Snoop-c/RC FACT/FACT conveyor | D4: FCT/DFU/SOC | E4: FCT/DFU/SOC | F4: Flex FCT/Flex Mic/FCT | G4: Panel DFU/FCT/GK FCT/BI/Conveyor/Bamboo/Marge&X-talk | H4: Grape/Helios/FACT & VENT /Snoop C
A5: PRM | B5: Station Total Demand | C5: {=SUM(C6:C13)} -> 73 | D5: {=SUM(D6:D13)} -> 42 | E5: {=SUM(E6:E13)} -> 59 | F5: {=SUM(F6:F13)} -> 72 | G5: {=SUM(G6:G13)} -> 56 | H5: {=SUM(H6:H13)} -> 172
A6: PRM | B6: PM | C6: {=2+5} -> 7 | D6: 2 | E6: {=3+1} -> 4 | F6: {=7+2} -> 9 | G6: {=2+2+2} -> 6 | H6: {=8+4} -> 12
A7: PRM | B7: ME | C7: {=5+7} -> 12 | D7: 5 | E7: {=5+2} -> 7 | F7: {=5+3} -> 8 | G7: {=3+2+1} -> 6 | H7: {=10+13} -> 23
A8: PRM | B8: EE | C8: {=1+10} -> 11 | D8: 8 | E8: {=8+2} -> 10 | F8: {=8+1} -> 9 | G8: {=5+1+2} -> 8 | H8: {=6+10} -> 16
A9: PRM | B9: SW | C9: {=1+6+3} -> 10 | D9: 8 | E9: {=6+2} -> 8 | F9: {=10+1} -> 11 | G9: {=3+1} -> 4 | H9: 2
A10: PRM | B10: FAE | C10: {=4+4} -> 8 | D10: 8 | E10: {=8+1} -> 9 | F10: {=9+3} -> 12 | G10: {=3+1+4} -> 8 | H10: 22
A11: PRM | B11: Assembly | C11: 14 | D11: 5 | E11: 8 | F11: 12 | G11: 15 | H11: {=13+18+18+8} -> 57
A12: PRM | B12: Debug | C12: 6 | D12: 3 | E12: 7 | F12: 6 | G12: 5 | H12: {=6+6+13} -> 25
A13: PRM | B13: Quality | C13: 5 | D13: 3 | E13: 6 | F13: 5 | G13: 4 | H13: {=7+8} -> 15
A14: PRM | B14: VE | H14: 6

Sheet Y2027 NPI - Innorev (Fiona) - R
A1: Resource Availability for Y2027 NPI Support
A2: SI Name | B2: Resource | C2: Y2026 Loading (Apr’26 ~ Sep’26) | D2: Total Resource (Cut Off Apr wk3) | E2: Resource Occupied for Y2026 Ramp (Apr’26 ~ Sep’26) | F2: Resource Leftover for Y2027 Brand-New Station NPI Build (Apr’26 ~ Sep’26) | G2: # of Stations Type can support (Refer CPT Y2027 RFP) | H2: Station Name can support (Refer CPT Y2027 RFP) | I2: Justification on why resource can support | J2: Space Supportability (Y/N) | K2: Machining Capacity Supportability (Y/N) | L2: Assembly Capacity Supportability (Y/N) | M2: Quality Capacity Supportability (Y/N) | N2: Station Name CANNOT Support (Refer CPT Y2027 RFP) & Justification
A3: Innorev | B3: PM | C3: {=SUM(E3:E10)/SUM(D3:D10)} -> 0.51492537 | D3: 24 | E3: 8 | F3: {=D3-E3} -> 16 | G3: 2x, conveyor and standalone with a design assumptions i.e similar as Scarlet/ASL-P/DVI/IMU conveyor and SA standalone stations. | H3: iPhone V7x Station ALS-P Conveyor, Odin Conveyor, DCR/OS Tests, IQC AA stations. iPad J8x7 Station DVI Conveyor Watch N25x Station FACT21&Vent2 Conveyor, Conveyor Cyan Rotary Audio B798 station All in One Case, Open Short, IMU Camera. | I3: Refer to Mistral DVI Conveyor,V6x SA standalone and other QT stations,we had experience in similar complexity, NPI resourced required as below: IPhone V7x ALS-P Conveyor: ME - 2x EE - 2x TPM -2x OSS - 2x IPhone V7x DCR /OS test and IQC AA stations: ME - 2x EE - 1x TPM - 1x OSS - 2x IPad J8x7 DVI Conveyor: ME - 2x EE - 2x TPM - 1x OSS - 2x Watch N25x FACT21&VANT2 Conveyor: ME - 3x EE - 3x TPM - 1x OSS - 2x Watch N25x Conveyor Cyan: ME - 3x EE - 3x TPM - 1x OSS - 2x Audio B798 All in One Case and Open Short ME - 1x EE - 1x TPM - 1x OSS - 1x Audio B798 IMU Camera ME - 2x EE - 1x TPM - 1x OSS - 1x | J3: Y | K3: Y | L3: Y | M3: Y | N3: 1. IPhone V7x Station Odin Conveyor-SQE limiitation.
A4: Innorev | B4: ME | D4: 78 | E4: 11 | F4: {=D4-E4} -> 67
A5: Innorev | B5: EE | D5: 29 | E5: 7 | F5: {=D5-E5} -> 22
A6: Innorev | B6: SW | D6: 0 | E6: 0 | F6: {=D6-E6} -> 0
A7: Innorev | B7: FAE | D7: 9 | E7: 4 | F7: {=D7-E7} -> 5
A8: Innorev | B8: Assembly | D8: 208 | E8: 140 | F8: {=D8-E8} -> 68
A9: Innorev | B9: Debug | D9: 32 | E9: 20 | F9: {=D9-E9} -> 12
A10: Innorev | B10: Quality | D10: 22 | E10: 17 | F10: {=D10-E10} -> 5

Sheet Y2027 NPI - Innorev (Fiona) - Y
A1: Y2026 Loading Breakdown (Apr ~ Sep)
A2: SI Name | B2: Items | C2: Portable | D2: Pad | E2: Audio | F2: Watch | G2: Phone
A3: Innorev | B3: Program | C3: J91a | D3: J510 | E3: B868/B790 | F3: N23x | G3: V6x/Mistral
A4: Innorev | B4: Station Name | C4: Button/CBT/Trackpad Force/DVI/QT0/USBC/QT1/SWDL/Actuation/Impedance | D4: ALS Cal/CCB/Freyr/DVI/ISD/QT1/CT1/Janus | E4: Kinneret/Grid Flare/Shipping setting/All in one/SA-QT2/Burn in/SA-QT1/QT1/FWDL/Smart Charging/Gatekeeper | F4: ALS-COMBO/Magnetizer/InterConnect/Reflow line/Loading/Unloading | G4: Jasmine/Magnolia/IMU Conveyor/DVI Conveyor/ALS-P/Scarlet/Scarlet IMU/Alpha/Vent2/ISD
A5: Innorev | B5: Station Total Demand | C5: 10 | D5: 8 | E5: 11 | F5: 6 | G5: 10
A6: Innorev | B6: PM | C6: 3 | D6: 7 | E6: 4 | F6: 2 | G6: 8
A7: Innorev | B7: ME | C7: 10 | D7: 16 | E7: 11 | F7: 8 | G7: 33
A8: Innorev | B8: EE | C8: 2 | D8: 6 | E8: 4 | F8: 5 | G8: 12
A9: Innorev | B9: SW | C9: 0 | D9: 0 | E9: 0 | F9: 0 | G9: 0
A10: Innorev | B10: FAE | C10: 1 | D10: 3 | E10: 1 | F10: 1 | G10: 3
A11: Innorev | B11: Assembly | C11: 7 | D11: 58 | E11: 33 | F11: 22 | G11: 88
A12: Innorev | B12: Debug | C12: 1 | D12: 9 | E12: 5 | F12: 3 | G12: 14
A13: Innorev | B13: Quality | C13: 2 | D13: 6 | E13: 3 | F13: 1 | G13: 10

Sheet Y2027 NPI - JLK (Sean) - Resour
A1: Resource Availability for Y2027 NPI Support
A2: SI Name | B2: Resource | C2: Y2026 Loading (Apr’26 ~ Sep’26) | D2: Total Resource (Cut Off Apr wk3) | E2: Resource Occupied for Y2026 Ramp (Apr’26 ~ Sep’26) | F2: Resource Leftover for Y2027 Brand-New Station NPI Build (Apr’26 ~ Sep’26) | G2: # of Stations Type can support (Refer CPT Y2027 RFP) | H2: Station Name can support (Refer CPT Y2027 RFP) | I2: Justification on why resource can support | J2: Space Supportability (Y/N) | K2: Machining Capacity Supportability (Y/N) | L2: Assembly Capacity Supportability (Y/N) | M2: Quality Capacity Supportability (Y/N) | N2: Station Name CANNOT Support (Refer CPT Y2027 RFP) & Justification
A3: JLK | B3: PM | C3: {=SUM(E3:E10)/SUM(D3:D10)} -> 0.59375 | D3: 15 | E3: 9 | F3: {=D3-E3} -> 6 | G3: 7x | H3: iPhone V7x Station SA-Barbie iPhone V7x Station Odin Conveyor iPhone V7x Station ALS-P Conveyor iPad J8x7 station DVI Conveyor Audio B798 Station Touch Conveyor Audio B798 Station Force Conveyor Audio B798 Station FACT Conveyor | I3: Refer to V6x SA-Ringo, V6x Odin + Clematis, V6x ALS-P, V6x DVI, B790 Touch, FACT, Force station in similar complexity, NPI resourced required as below: ME - 12x EE - 5x SW- 4x | J3: Y | K3: Y | L3: Y | M3: Y | N3: Watch N25x Station FACT & Vent Conveyor - Resource limitation & Watch N25x Station Cyan Conveyor - Resource limitation Portable 91a Station caramel Conveyor—Tie P2 validation schedule, cannot catch up build date
A4: JLK | B4: ME | D4: {=12+2+12+4} -> 30 | E4: 9 | F4: {=D4-E4} -> 21
A5: JLK | B5: EE | D5: 12 | E5: 7 | F5: {=D5-E5} -> 5
A6: JLK | B6: SW | D6: 8 | E6: 4 | F6: {=D6-E6} -> 4
A7: JLK | B7: FAE | D7: 25 | E7: 17 | F7: {=D7-E7} -> 8
A8: JLK | B8: Assembly | D8: 150 | E8: 86 | F8: {=D8-E8} -> 64
A9: JLK | B9: Debug | D9: 60 | E9: 43 | F9: {=D9-E9} -> 17
A10: JLK | B10: Quality | D10: 20 | E10: 15 | F10: {=D10-E10} -> 5

Sheet Y2027 NPI - JLK (Sean) - Y2026 
A1: Y2026 Loading Breakdown (Apr ~ Sep)
A2: SI Name | B2: Items | C2: Portable | D2: Pad | E2: Audio | F2: Watch | G2: Phone
B3: Program | C3: K11P | D3: J510/J581/B001 | E3: B790/B868 | F3: N24x | G3: V6x/V68
B4: Station Name | C4: KB PEM/ALS CAL/ALS_X-talk/Grape/ISD Standalone | D4: Grape Test/ALS CAL/System Test Standalone | E4: Touch Cal/Prox/Regia/LED Standalone | F4: Grape | G4: FACT/ALS/A-AMAI/Hydros/Barbie Standalone FACT & Vent /DVI/Grape Conveyor
B5: Station Total Demand | C5: 111 | D5: {=4+54} -> 58 | E5: {=120+12*4+8} -> 176 | F5: 15 | G5: {=189+219} -> 408
B6: PM | C6: 2 | D6: 1 | E6: 2 | F6: 1 | G6: 3
B7: ME | C7: 2 | D7: 1 | E7: 2 | F7: 1 | G7: 3
B8: EE | C8: 2 | D8: 1 | E8: 1 | F8: 1 | G8: 2
B9: SW | C9: 1 | D9: 0 | E9: 1 | F9: 0 | G9: 2
B10: FAE | C10: 3 | D10: 2 | E10: 1 | F10: 1 | G10: 10
B11: Assembly | C11: 13 | D11: 3 | E11: 5 | F11: 2 | G11: {=38+25} -> 63
B12: Debug | C12: 5 | D12: 2 | E12: 2 | F12: 1 | G12: {=18+15} -> 33
B13: Quality | C13: 2 | D13: 1 | E13: 1 | F13: 1 | G13: 10

Sheet Y2027 NPI - Cencorp (Rick) - Re
A1: Resource Availability for Y2027 NPI Support
A2: SI Name | B2: Resource | C2: Y2026 Loading (Apr’26 ~ Sep’26) | D2: Total Resource (Cut Off Apr wk3) | E2: Resource Occupied for Y2026 Ramp (Apr’26 ~ Sep’26) | F2: Resource Leftover for Y2027 Brand-New Station NPI Build (Apr’26 ~ Sep’26) | G2: Cencorp Plan Resource Allocated to Y2027 RFP (Apr’26 ~ Sep’26) | H2: Leftover Resource after allocated to Y2027 RFP | I2: # of Stations Type can support (Refer CPT Y2027 RFP) | J2: Station Name can support (Refer CPT Y2027 RFP) | K2: Justification on why resource can support | L2: Space Supportability (Y/N) | M2: Machining Capacity Supportability (Y/N) | N2: Assembly Capacity Supportability (Y/N) | O2: Quality Capacity Supportability (Y/N) | P2: Station Name CANNOT Support (Refer CPT Y2027 RFP) & Justification
A3: Cencorp | B3: PM/TPM | C3: {=SUM(E3:E7)/SUM(D3:D7)} -> 0.49079755 | D3: 31 | E3: 15 | F3: {=D3-E3} -> 16 | G3: {=SUM('Y2027 NPI - Cencorp (Rick) - Y2'!C6:J6)} -> 8.5 | H3: {=F3-G3} -> 7.5 | I3: Cencorp can take maximum 8x RFP stations as they are currently engaged (see column J details). Any additional RFP will be medium-high risk to Cencorp according to their leftover engineering resources (see column H details) | J3: J807/J830 iPad DVI N25x Watch Bamboo FACT N25x Watch Bamboo Cyan V7x iPhone Odim V7x iPhone ALS-P V7x iPhone SA Barbie K12P Portable Seasalt K104 Portable Volga | K3: 1. Total leftover PM&RD resource for brand-new stations is about 49% 2. Leftover engineering resources allocation matrix plan showing able to support current engaged 8x RFP stations | L3: Taicang Total：6000 Everest MP: 2000 Everest NPI: 500 Others: 2000 Leftover: 1500 Zhuhai Total：3500 Everest MP: 2100 Everest NPI:300 Others: 800 Leftover: 300 | M3: Y | N3: Y | O3: Y
A4: Cencorp | B4: ME | D4: 43 | E4: 21.5 | F4: {=D4-E4} -> 21.5 | G4: {=SUM('Y2027 NPI - Cencorp (Rick) - Y2'!C7:J7)} -> 15 | H4: {=F4-G4} -> 6.5
A5: Cencorp | B5: EE | D5: 36 | E5: 20 | F5: {=D5-E5} -> 16 | G5: {=SUM('Y2027 NPI - Cencorp (Rick) - Y2'!C8:J8)} -> 12 | H5: {=F5-G5} -> 4
A6: Cencorp | B6: SW | D6: 20 | E6: 5 | F6: {=D6-E6} -> 15 | G6: {=SUM('Y2027 NPI - Cencorp (Rick) - Y2'!C9:J9)} -> 3.5 | H6: {=F6-G6} -> 11.5
A7: Cencorp | B7: FAE | D7: 33 | E7: 18.5 | F7: {=D7-E7} -> 14.5 | G7: {=SUM('Y2027 NPI - Cencorp (Rick) - Y2'!C10:J10)} -> 10 | H7: {=F7-G7} -> 4.5
A8: Cencorp | B8: Assembly | C8: {=SUM(E8:E9)/SUM(D8:D9)} -> 0.74484536 | D8: 268 | E8: 232 | F8: {=D8-E8} -> 36
A9: Cencorp | B9: Debug | D9: 120 | E9: 57 | F9: {=D9-E9} -> 63
A10: Cencorp | B10: Quality | C10: {=SUM(E10)/SUM(D10)} -> 0.76 | D10: 25 | E10: 19 | F10: {=D10-E10} -> 6 | G10: {=SUM('Y2027 NPI - Cencorp (Rick) - Y2'!C11:J11)} -> 5.5 | H10: {=F10-G10} -> 0.5

Sheet Y2027 NPI - Cencorp (Rick) - Y2
A1: Y2027 RFP Breakdown
A2: SI Name | B2: Items | C2: Portable | D2: Portable | E2: Pad | F2: Watch | G2: Watch | H2: Phone | I2: Phone | J2: Phone
A3: Cencorp | B3: Program | C3: K12p | D3: K104 | E3: J807/J830 | F3: N25x | G3: N25x | H3: V7x | I3: V7x | J3: V7x
A4: Cencorp | B4: Station Name | C4: Seasalt | D4: Volga | E4: DVI | F4: Bamboo FACT | G4: Bamboo Cyan | H4: Odim | I4: ALS-P | J4: SA Barbie
A5: Cencorp | B5: Station Total Demand | C5: / | D5: / | E5: / | F5: / | G5: / | H5: / | I5: / | J5: /
A6: Cencorp | B6: PM | C6: 2.5 | D6: 1.5 | E6: 1 | F6: 0.5 | G6: 0.5 | H6: 0.5 | I6: 1 | J6: 1
A7: Cencorp | B7: ME | C7: 3 | D7: 3 | E7: 2 | F7: 1 | G7: 1 | H7: 1 | I7: 3 | J7: 1
A8: Cencorp | B8: EE | C8: 3 | D8: 3 | E8: 1 | F8: 0.7 | G8: 0.3 | H8: 1 | I8: 2 | J8: 1
A9: Cencorp | B9: SW | C9: 0.5 | D9: 0.5 | E9: 0.5 | F9: 0.3 | G9: 0.2 | H9: 0.5 | I9: 0.5 | J9: 0.5
A10: Cencorp | B10: FAE | C10: 2.5 | D10: 1.5 | E10: 1 | F10: 0.5 | G10: 0.5 | H10: 1 | I10: 2 | J10: 1
A11: Cencorp | B11: Quality | C11: 1.5 | D11: 1 | E11: 0.5 | F11: 0.5 | G11: 0.5 | H11: 0.5 | I11: 0.5 | J11: 0.5

Sheet Y2027 NPI - Cencorp (Rick) - Y1
A1: Y2026 MP Loading Breakdown (Apr ~ Sep)
A2: SI Name | B2: Items | C2: Portable | D2: Pad | E2: Audio | F2: Watch | G2: Phone
A3: Cencorp | B3: Program | C3: J700 / K11p / J91A/ J701 | F3: N23x | G3: V68/V6x
A4: Cencorp | B4: Station Name | C4: Chocolate Seasalt Caramel Nile | F4: Bamboo 2.0 | G4: V68 Magnolia Plus XDXT Hydros Barbie T/V/Salvage V6x Jasmine Clematis Magnolia DVI Barbie V68/V6x MLB AP Stations
A5: Cencorp | B5: Station Total Demand | C5: SeaSalt PRB x 2 SeaSalt PVT x 1 Caramel OVB x1 Nile MP x 4 | F5: Bamboo 2.0 x 4 | G5: V68 NB x 123 RF x 80 V6x NB x 14 RF x 159 V6x/V68 MLB AP NB x 600
A6: Cencorp | B6: PM | C6: 6 | F6: 1 | G6: 8
A7: Cencorp | B7: ME | C7: 8.5 | F7: 3 | G7: 10
A8: Cencorp | B8: EE | C8: 9 | F8: 2 | G8: 9
A9: Cencorp | B9: SW | C9: 1 | F9: 1 | G9: 3
A10: Cencorp | B10: FAE | C10: 7.5 | F10: 1 | G10: 10
A11: Cencorp | B11: Assembly
A12: Cencorp | B12: Debug
A13: Cencorp | B13: Quality | C13: 5 | F13: 2 | G13: 12

Sheet Y2027 NPI - Cencorp (Rick) - Y3
A1: Y2026 MP Matrix
A2: Project | B2: PM | C2: ME | D2: EE | E2: SW | F2: FAE | G2: Quality
A3: Magnolia Plus | B3: 1 | C3: 2 | D3: 2 | E3: 1 | F3: 3 | G3: 2
A4: XDXT | B4: 1 | C4: 1 | D4: 1 | F4: 1 | G4: 1
A5: Hydros | B5: 1 | C5: 1 | D5: 1 | F5: 1 | G5: 1
A6: Barbie T/V | B6: 1 | C6: 1 | D6: 1 | E6: 0.5 | F6: 0.5 | G6: 2
A7: Jasmine | B7: 0.5 | C7: 0.5 | D7: 0.5 | F7: 0.5 | G7: 1
A8: Clematis | B8: 0.5 | C8: 0.5 | D8: 0.5 | F8: 0.5 | G8: 1
A9: Magnolia | B9: 0.5 | C9: 0.5 | D9: 0.5 | F9: 0.5 | G9: 1
A10: DVI | B10: 0.5 | C10: 0.5 | D10: 0.5 | E10: 1 | F10: 0.5 | G10: 1
A11: Barbie | B11: 0.5 | C11: 0.5 | D11: 0.5 | E11: 0.5 | F11: 0.5 | G11: 1
A12: MLB | B12: 0.5 | C12: 2.5 | D12: 1.5 | F12: 0.5 | G12: 1
A13: Chocolate | B13: 0.5 | C13: 0.5 | D13: 1 | F13: 1.5 | G13: 1
A14: Seasalt | B14: 2.5 | C14: 3 | D14: 3 | E14: 0.5 | F14: 2.5 | G14: 1.5
A15: Caramel | B15: 2.5 | C15: 3 | D15: 3 | E15: 0.5 | F15: 2.5 | G15: 1.5
A16: Nile | B16: 0.5 | C16: 2 | D16: 2 | F16: 1 | G16: 1
A17: Bamboo | B17: 2 | C17: 3 | D17: 2 | E17: 1 | F17: 2 | G17: 2

Sheet Y2027 NPI - HVS (Gene) - Resour
A1: Resource Availability for Y2027 NPI Support
A2: SI Name | B2: Resource | C2: Y2026 Loading (Apr’26 ~ Sep’26) | D2: Total Resource (Cut Off Apr wk3) | E2: Resource Occupied for Y2026 Ramp (Apr’26 ~ Sep’26) | F2: Resource Leftover for Y2027 Brand-New Station NPI Build (Apr’26 ~ Sep’26) | G2: # of Stations Type can support (Refer CPT Y2027 RFP) | H2: Station Name can support (Refer CPT Y2027 RFP) | I2: Justification on why resource can support | J2: Space Supportability (Y/N) | K2: Machining Capacity Supportability (Y/N) | L2: Assembly Capacity Supportability (Y/N) | M2: Quality Capacity Supportability (Y/N) | N2: Station Name CANNOT Support (Refer CPT Y2027 RFP) & Justification
A3: HVS | B3: PM | C3: {=SUM(E3:E10)/SUM(D3:D10)} -> 0.63953488 | D3: 8 | E3: 5 | F3: {=D3-E3} -> 3 | G3: 2x | H3: iPhone V7x Station ALS-P Audio Open Short All-in-onc / IMU Camera / Open Conveyor | I3: Refer to V6x ALSP station in similar complexity, NPI resourced required as below: PM- 1x ME - 4x EE - 1x Assembly：15/line Quality- 1x | J3: Y | K3: Y | L3: Y | M3: Y | N3: iPhone V7x Station Odin / DCR / IQA AA Watch Conveyor Fact/Vent, Rotary
A4: HVS | B4: ME | D4: 25 | E4: 16 | F4: {=D4-E4} -> 9
A5: HVS | B5: EE | D5: 7 | E5: 4 | F5: {=D5-E5} -> 3
A6: HVS | B6: SW | D6: 12 | E6: 7 | F6: {=D6-E6} -> 5
A7: HVS | B7: FAE | D7: 56 | E7: 43 | F7: {=D7-E7} -> 13
A8: HVS | B8: Assembly | D8: 98 | E8: 50 | F8: {=D8-E8} -> 48
A9: HVS | B9: Debug | D9: 32 | E9: 24 | F9: {=D9-E9} -> 8
A10: HVS | B10: Quality | D10: 20 | E10: 16 | F10: {=D10-E10} -> 4

Sheet Y2027 NPI - HVS (Gene) - Y2026 
A1: Y2026 Loading Breakdown (Apr ~ Sep)
A2: SI Name | B2: Items | C2: Portable | D2: Pad | E2: Desktop | F2: Audio | G2: Watch | H2: Phone
A3: PRM | B3: Program | C3: J701/K104/J91a/K11p | D3: J8x7/J9xx/J510 | E3: J775/J873/J883/J83x | F3: B798/B868/B790/B747a/B727 | G3: N23x/N240 | H3: V68/V6X
A4: PRM | B4: Station Name | C4: Snoop/Snoop-c/RC FACT/FACT conveyor | D4: FCT/DFU/SOC | E4: FCT/DFU/SOC | F4: Flex FCT/Flex Mic/FCT | G4: Panel DFU/FCT/GK FCT/BI/Conveyor/Bamboo/Marge&X-talk | H4: Grape/Helios/FACT & VENT /Snoop C
A5: PRM | B5: Station Total Demand | C5: {=SUM(C6:C13)} -> 73 | D5: {=SUM(D6:D13)} -> 42 | E5: {=SUM(E6:E13)} -> 59 | F5: {=SUM(F6:F13)} -> 72 | G5: {=SUM(G6:G13)} -> 56 | H5: {=SUM(H6:H13)} -> 172
A6: PRM | B6: PM | C6: {=2+5} -> 7 | D6: 2 | E6: {=3+1} -> 4 | F6: {=7+2} -> 9 | G6: {=2+2+2} -> 6 | H6: {=8+4} -> 12
A7: PRM | B7: ME | C7: {=5+7} -> 12 | D7: 5 | E7: {=5+2} -> 7 | F7: {=5+3} -> 8 | G7: {=3+2+1} -> 6 | H7: {=10+13} -> 23
A8: PRM | B8: EE | C8: {=1+10} -> 11 | D8: 8 | E8: {=8+2} -> 10 | F8: {=8+1} -> 9 | G8: {=5+1+2} -> 8 | H8: {=6+10} -> 16
A9: PRM | B9: SW | C9: {=1+6+3} -> 10 | D9: 8 | E9: {=6+2} -> 8 | F9: {=10+1} -> 11 | G9: {=3+1} -> 4 | H9: 2
A10: PRM | B10: FAE | C10: {=4+4} -> 8 | D10: 8 | E10: {=8+1} -> 9 | F10: {=9+3} -> 12 | G10: {=3+1+4} -> 8 | H10: 22
A11: PRM | B11: Assembly | C11: 14 | D11: 5 | E11: 8 | F11: 12 | G11: 15 | H11: {=13+18+18+8} -> 57
A12: PRM | B12: Debug | C12: 6 | D12: 3 | E12: 7 | F12: 6 | G12: 5 | H12: {=6+6+13} -> 25
A13: PRM | B13: Quality | C13: 5 | D13: 3 | E13: 6 | F13: 5 | G13: 4 | H13: {=7+8} -> 15
A14: PRM | B14: VE | H14: 6

Sheet Y2027 NPI - Pantamaster (JS) - 
A1: Resource Availability for Y2027 NPI Support
A2: SI Name | B2: Resource | C2: Y2026 Loading (Apr’26 ~ Sep’26) | D2: Total Resource (Cut Off Apr wk3) | E2: Resource Occupied for Y2026 Ramp (Apr’26 ~ Sep’26) | F2: Resource Leftover for Y2027 Brand-New Station NPI Build (Apr’26 ~ Sep’26) | G2: # of Stations Type can support (Refer CPT Y2027 RFP) | H2: Station Name can support (Refer CPT Y2027 RFP) | I2: Justification on why resource can support | J2: Space Supportability (Y/N) | K2: Machining Capacity Supportability (Y/N) | L2: Assembly Capacity Supportability (Y/N) | M2: Quality Capacity Supportability (Y/N) | N2: Station Name CANNOT Support (Refer CPT Y2027 RFP) & Justification
A3: Pentamaster | B3: PM | C3: {=SUM(E3:E10)/SUM(D3:D10)} -> 0.74117647 | D3: 11 | E3: 9 | F3: {=D3-E3} -> 2 | G3: 1x | H3: iPhone V7x Station SA-Barbie | I3: Refer to V7x SA Barbie station in similar complexity, NPI resourced required as below: PM - 1x ME - 1x EE - 1x SW - 1x FAE - 1x (China) Assembly - 2x Debug - 1x Quality - 1x | J3: Y | K3: Y | L3: Y | M3: Y | N3: -
A4: Pentamaster | B4: ME | D4: 6 | E4: 4 | F4: {=D4-E4} -> 2
A5: Pentamaster | B5: EE | D5: 4 | E5: 3 | F5: {=D5-E5} -> 1
A6: Pentamaster | B6: SW | D6: 9 | E6: 6 | F6: {=D6-E6} -> 3
A7: Pentamaster | B7: FAE | D7: 20 | E7: 16 | F7: {=D7-E7} -> 4
A8: Pentamaster | B8: Assembly | D8: 20 | E8: 15 | F8: {=D8-E8} -> 5
A9: Pentamaster | B9: Debug | D9: 10 | E9: 7 | F9: {=D9-E9} -> 3
A10: Pentamaster | B10: Quality | D10: 5 | E10: 3 | F10: {=D10-E10} -> 2

Sheet Y2027 NPI - Pantamaster (JS) -1
A1: Y2026 Loading Breakdown (Apr ~ Sep)
A2: SI Name | B2: Items | C2: Portable | D2: Pad | E2: Audio | F2: Watch | G2: Phone
A3: Pentamaster | B3: Program | C3: J62x | G3: V6x
A4: Pentamaster | B4: Station Name | C4: Chamber Conveyor | G4: BEXT XDXT FISH
A5: Pentamaster | B5: Station Total Demand | C5: 0 | G5: 5
A6: Pentamaster | B6: PM | C6: - | G6: 9
A7: Pentamaster | B7: ME | C7: - | G7: 4
A8: Pentamaster | B8: EE | C8: - | G8: 3
A9: Pentamaster | B9: SW | C9: - | G9: 6
A10: Pentamaster | B10: FAE | C10: 1 | G10: 15
A11: Pentamaster | B11: Assembly | C11: - | G11: 15
A12: Pentamaster | B12: Debug | C12: - | G12: 7
A13: Pentamaster | B13: Quality | C13: - | G13: 3

Sheet Y2027 NPI - CYG (Rick) - Resour
A1: Resource Availability for Y2027 NPI Support
A2: SI Name | B2: Resource | C2: Y2026 Loading (Apr’26 ~ Sep’26) | D2: Total Resource (Cut Off Apr wk3) | E2: Resource Occupied for Y2026 Ramp (Apr’26 ~ Sep’26) | F2: Resource Leftover for Y2027 Brand-New Station NPI Build (Apr’26 ~ Sep’26) | G2: # of Stations Type can support (Refer CPT Y2027 RFP) | H2: Station Name can support (Refer CPT Y2027 RFP) | I2: Justification on why resource can support | J2: Space Supportability (Y/N) | K2: Machining Capacity Supportability (Y/N) | L2: Assembly Capacity Supportability (Y/N) | M2: Quality Capacity Supportability (Y/N) | N2: Station Name CANNOT Support (Refer CPT Y2027 RFP) & Justification
B3: PM | C3: {=SUM(E3:E10)/SUM(D3:D10)} -> 0.4842615 | D3: 37 | E3: {=ROUNDUP('Y2027 NPI - CYG (Rick) - Y2026 '!C6+'Y2027 NPI - CYG (Rick) - Y2026 '!D6+'Y2027 NPI - CYG (Rick) - Y2026 '!E6+'Y2027 NPI - CYG (Rick) - Y2026 '!F6+'Y2027 NPI - CYG (Rick) - Y2026 '!G6+'Y2027 NPI - CYG (Rick) - Y2026 '!H6+'Y2027 NPI - CYG (Rick) - Y2026 '!I6,0)} -> 11 | F3: {=D3-E3} -> 26 | G3: 15x | H3: 1: Portable K12p DFU/FCT/SOC; 2: Portable K104 DFU/FCT/SOC; 3: Pad J8x7 SOC; 4: Audio J727 DFU/FCT; 5: Phone V7x SA Carrier&Socket&Pogo&Tray&Holder&DCR | I3: 1: Portable K12p DFU/FCT/SOC: Refer to K11p DFU/FCT/SOC station in similar complexity, NPI resourced required as below: ME - 2x, EE - 6x, SW - 1x, FAE - 6x; 2: Portable K104 DFU/FCT/SOC: Refer to J804 DFU/FCT/SOC station in similar complexity, NPI resourced required as below: ME - 1x, EE - 2x, SW - 1x, FAE - 2x; 3: Pad J8x7 SOC: Refer to Pad J7x7 MFCT station in similar complexity, NPI resourced required as below: ME - 1x, EE - 1x, FAE - 1x; 4: Audio J727 DFU/FCT: Refer to J747 DFU/FCT station in similar complexity, NPI resourced required as below: ME - 2x, EE - 2x, SW - 1x, FAE 2x; 5: Phone V7x SA Carrier&Socket&Pogo&Tray&Holder&DCR: Refer to V6x SA Carrier&Socket&Pogo&Tray&Holder&DCR station in similar complexity, NPI resourced required as below: ME - 3x, EE - 3x, SW - 1x, FAE 1x; | J3: Y | K3: Y | L3: Y | M3: Y | N3: N/A
B4: ME | D4: 42 | E4: {=ROUNDUP('Y2027 NPI - CYG (Rick) - Y2026 '!C7+'Y2027 NPI - CYG (Rick) - Y2026 '!D7+'Y2027 NPI - CYG (Rick) - Y2026 '!E7+'Y2027 NPI - CYG (Rick) - Y2026 '!F7+'Y2027 NPI - CYG (Rick) - Y2026 '!G7+'Y2027 NPI - CYG (Rick) - Y2026 '!H7+'Y2027 NPI - CYG (Rick) - Y2026 '!I7,0)} -> 11 | F4: {=D4-E4} -> 31
B5: EE | D5: 43 | E5: {=ROUNDUP('Y2027 NPI - CYG (Rick) - Y2026 '!C8+'Y2027 NPI - CYG (Rick) - Y2026 '!D8+'Y2027 NPI - CYG (Rick) - Y2026 '!E8+'Y2027 NPI - CYG (Rick) - Y2026 '!F8+'Y2027 NPI - CYG (Rick) - Y2026 '!G8+'Y2027 NPI - CYG (Rick) - Y2026 '!H8+'Y2027 NPI - CYG (Rick) - Y2026 '!I8,0)} -> 9 | F5: {=D5-E5} -> 34
B6: SW | D6: 22 | E6: {=ROUNDUP('Y2027 NPI - CYG (Rick) - Y2026 '!C9+'Y2027 NPI - CYG (Rick) - Y2026 '!D9+'Y2027 NPI - CYG (Rick) - Y2026 '!E9+'Y2027 NPI - CYG (Rick) - Y2026 '!F9+'Y2027 NPI - CYG (Rick) - Y2026 '!G9+'Y2027 NPI - CYG (Rick) - Y2026 '!H9+'Y2027 NPI - CYG (Rick) - Y2026 '!I9,0)} -> 5 | F6: {=D6-E6} -> 17
B7: FAE | D7: 48 | E7: {=ROUNDUP('Y2027 NPI - CYG (Rick) - Y2026 '!C10+'Y2027 NPI - CYG (Rick) - Y2026 '!D10+'Y2027 NPI - CYG (Rick) - Y2026 '!E10+'Y2027 NPI - CYG (Rick) - Y2026 '!F10+'Y2027 NPI - CYG (Rick) - Y2026 '!G10+'Y2027 NPI - CYG (Rick) - Y2026 '!H10+'Y2027 NPI - CYG (Rick) - Y2026 '!I10,0)} -> 15 | F7: {=D7-E7} -> 33
B8: Assembly | D8: 135 | E8: {=ROUNDUP('Y2027 NPI - CYG (Rick) - Y2026 '!C11+'Y2027 NPI - CYG (Rick) - Y2026 '!D11+'Y2027 NPI - CYG (Rick) - Y2026 '!E11+'Y2027 NPI - CYG (Rick) - Y2026 '!F11+'Y2027 NPI - CYG (Rick) - Y2026 '!G11+'Y2027 NPI - CYG (Rick) - Y2026 '!H11+'Y2027 NPI - CYG (Rick) - Y2026 '!I11,0)} -> 96 | F8: {=D8-E8} -> 39
B9: Debug | D9: 64 | E9: {=ROUNDUP('Y2027 NPI - CYG (Rick) - Y2026 '!C12+'Y2027 NPI - CYG (Rick) - Y2026 '!D12+'Y2027 NPI - CYG (Rick) - Y2026 '!E12+'Y2027 NPI - CYG (Rick) - Y2026 '!F12+'Y2027 NPI - CYG (Rick) - Y2026 '!G12+'Y2027 NPI - CYG (Rick) - Y2026 '!H12+'Y2027 NPI - CYG (Rick) - Y2026 '!I12,0)} -> 39 | F9: {=D9-E9} -> 25
B10: Quality | D10: 22 | E10: {=ROUNDUP('Y2027 NPI - CYG (Rick) - Y2026 '!C13+'Y2027 NPI - CYG (Rick) - Y2026 '!D13+'Y2027 NPI - CYG (Rick) - Y2026 '!E13+'Y2027 NPI - CYG (Rick) - Y2026 '!F13+'Y2027 NPI - CYG (Rick) - Y2026 '!G13+'Y2027 NPI - CYG (Rick) - Y2026 '!H13+'Y2027 NPI - CYG (Rick) - Y2026 '!I13,0)} -> 14 | F10: {=D10-E10} -> 8

Sheet Y2027 NPI - CYG (Rick) - Y2026 
A1: Y2026 MP Loading Breakdown (Apr ~ Sep)
A2: SI Name | B2: Items | C2: Portable | D2: Pad | E2: Audio | F2: Watch | G2: Phone | H2: Pencil | I2: Apple TV
B3: Program | C3: K11p/J804 | D3: J707/J737 (Already Finish MP Ramp by Y25 Q4) | E3: J747( Already finish MP Ramp by Y25 Q4) | F3: N23xN240 | G3: V6xV68 | H3: X3908 | I3: J529
B4: Station Name | C4: DFU/FCT/SOC | D4: MFCT | E4: DFU/FCT | F4: PFCT/PDFU/GK/Burnin/Combo CCD/Rioch/SA STHB/Sulu | G4: DFU/FCT/Carrier&Socket&Pogo&Tray&Holder&DCR Fixture | H4: SA QT/Aquila/Tip Power | I4: FCT/Button
B5: Station Total Demand | C5: 199 | D5: 24 | E5: 100 | F5: 1480x(Burnin 1039x; Other Station: 441x) | G5: 1368x (BT DFU/FCT: 359x ; SA Carrier&socket 1009x) | H5: 35 | I5: 39
B6: PM | C6: 2 | D6: 0.1 | E6: 0.1 | F6: 3 | G6: 4 | H6: 0.5 | I6: 0.5
B7: ME | C7: 1 | D7: 0.1 | E7: 0.1 | F7: 2 | G7: 6 | H7: 0.5 | I7: 0.5
B8: EE | C8: 1 | D8: 0.1 | E8: 0.1 | F8: 2 | G8: 4 | H8: 0.5 | I8: 0.5
B9: SW | C9: 1 | D9: 0.1 | E9: 0.1 | F9: 1 | G9: 1 | H9: 0.5 | I9: 0.5
B10: FAE | C10: 2 | D10: 0.1 | E10: 0.1 | F10: 5 | G10: 5 | H10: 1 | I10: 1
B11: Assembly | C11: 12 | D11: 0 | E11: 0 | F11: 36 | G11: 32 | H11: 8 | I11: 8
B12: Debug | C12: 5 | D12: 0 | E12: 0 | F12: 15 | G12: 14 | H12: 3 | I12: 2
B13: Quality | C13: 2 | D13: 0 | E13: 0 | F13: 6 | G13: 5 | H13: 0.5 | I13: 0.5

Sheet Y2027 NPI - Nextas (Jessie) - R
A1: Resource Availability for Y2027 NPI Support
A2: SI Name | B2: Resource | C2: Y2026 Loading (Apr’26 ~ Sep’26) | D2: Total Resource (Cut Off Apr wk3) | E2: Resource Occupied for Y2026 Ramp (Apr’26 ~ Sep’26) | F2: Resource Leftover for Y2027 Brand-New Station NPI Build (Apr’26 ~ Sep’26) | G2: # of Stations Type can support (Refer CPT Y2027 RFP) | H2: Station Name can support (Refer CPT Y2027 RFP) | I2: Justification on why resource can support | J2: Space Supportability (Y/N) | K2: Machining Capacity Supportability (Y/N) | L2: Assembly Capacity Supportability (Y/N) | M2: Quality Capacity Supportability (Y/N) | N2: Station Name CANNOT Support (Refer CPT Y2027 RFP) & Justification | O2: Bojay total resource
A3: Nextas | B3: PM | C3: {=SUM(E3:E10)/SUM(D3:D10)} -> 0.15728155 | D3: 59 | E3: 4 | F3: {=D3-E3} -> 55 | G3: 2x | H3: IQC AA stations DCR/OS Tests | I3: Refer to V64(RCAM IQC &RIM，FCAM-IQC&PAM，MLB modules in similar complexity, NPI resourced required as below: PM:4x ME - 4x EE - 3x FAE-5x Assembly:4 Quality: 3 | J3: Y | K3: Y | L3: Y | M3: Y | N3: No issue | O3: 98
A4: Nextas | B4: ME | D4: 52 | E4: 4 | F4: {=D4-E4} -> 48 | O4: 417
A5: Nextas | B5: EE | D5: 31 | E5: 3 | F5: {=D5-E5} -> 28 | O5: 210
A6: Nextas | B6: SW | D6: 53 | E6: 3 | F6: {=D6-E6} -> 50 | O6: 72
A7: Nextas | B7: FAE | D7: 95 | E7: 21 | F7: {=D7-E7} -> 74 | O7: 290
A8: Nextas | B8: Assembly | D8: 152 | E8: 22 | F8: {=D8-E8} -> 130 | O8: 266
A9: Nextas | B9: Debug | D9: 48 | E9: 21 | F9: {=D9-E9} -> 27 | O9: 103
A10: Nextas | B10: Quality | D10: 25 | E10: 3 | F10: {=D10-E10} -> 22 | O10: 87

Sheet Y2027 NPI - Nextas (Jessie) - Y
A1: Y2026 Loading Breakdown (Apr ~ Sep)
A2: SI Name | B2: Items | C2: Portable | D2: Pad | E2: Audio | F2: Watch | G2: Phone
A3: Nextas | B3: Program | G3: V7x
A4: Nextas | B4: Station Name | G4: IQC AA stations DCR/OS Tests
A5: Nextas | B5: Station Total Demand | G5: 2x
A6: Nextas | B6: PM | G6: 4
A7: Nextas | B7: ME | G7: 4
A8: Nextas | B8: EE | G8: 3
A9: Nextas | B9: SW | G9: 3
A10: Nextas | B10: FAE | G10: 21
A11: Nextas | B11: Assembly | G11: 22
A12: Nextas | B12: Debug | G12: 21
A13: Nextas | B13: Quality | G13: 3
